Traceback (most recent call last):
  File "/opt/hostedtoolcache/Python/3.9.19/x64/lib/python3.9/site-packages/jupyter_cache/executors/utils.py", line 58, in single_nb_execution
    executenb(
  File "/opt/hostedtoolcache/Python/3.9.19/x64/lib/python3.9/site-packages/nbclient/client.py", line 1314, in execute
    return NotebookClient(nb=nb, resources=resources, km=km, **kwargs).execute()
  File "/opt/hostedtoolcache/Python/3.9.19/x64/lib/python3.9/site-packages/jupyter_core/utils/__init__.py", line 165, in wrapped
    return loop.run_until_complete(inner)
  File "/opt/hostedtoolcache/Python/3.9.19/x64/lib/python3.9/asyncio/base_events.py", line 647, in run_until_complete
    return future.result()
  File "/opt/hostedtoolcache/Python/3.9.19/x64/lib/python3.9/site-packages/nbclient/client.py", line 709, in async_execute
    await self.async_execute_cell(
  File "/opt/hostedtoolcache/Python/3.9.19/x64/lib/python3.9/site-packages/nbclient/client.py", line 1062, in async_execute_cell
    await self._check_raise_for_error(cell, cell_index, exec_reply)
  File "/opt/hostedtoolcache/Python/3.9.19/x64/lib/python3.9/site-packages/nbclient/client.py", line 918, in _check_raise_for_error
    raise CellExecutionError.from_cell_and_msg(cell, exec_reply_content)
nbclient.exceptions.CellExecutionError: An error occurred while executing the following cell:
------------------
dhmoi.explore(legend=False)
------------------


[0;31m---------------------------------------------------------------------------[0m
[0;31mModuleNotFoundError[0m                       Traceback (most recent call last)
File [0;32m/opt/hostedtoolcache/Python/3.9.19/x64/lib/python3.9/site-packages/geopandas/explore.py:286[0m, in [0;36m_explore[0;34m(df, column, cmap, color, m, tiles, attr, tooltip, popup, highlight, categorical, legend, scheme, k, vmin, vmax, width, height, categories, classification_kwds, control_scale, marker_type, marker_kwds, style_kwds, highlight_kwds, missing_kwds, tooltip_kwds, popup_kwds, legend_kwds, map_kwds, **kwargs)[0m
[1;32m    285[0m [38;5;28;01mimport[39;00m [38;5;21;01mmatplotlib[39;00m[38;5;21;01m.[39;00m[38;5;21;01mpyplot[39;00m [38;5;28;01mas[39;00m [38;5;21;01mplt[39;00m
[0;32m--> 286[0m [38;5;28;01mfrom[39;00m [38;5;21;01mmapclassify[39;00m [38;5;28;01mimport[39;00m classify
[1;32m    288[0m [38;5;66;03m# isolate MPL version - GH#2596[39;00m

[0;31mModuleNotFoundError[0m: No module named 'mapclassify'

During handling of the above exception, another exception occurred:

[0;31mImportError[0m                               Traceback (most recent call last)
Cell [0;32mIn[109], line 1[0m
[0;32m----> 1[0m [43mdhmoi[49m[38;5;241;43m.[39;49m[43mexplore[49m[43m([49m[43mlegend[49m[38;5;241;43m=[39;49m[38;5;28;43;01mFalse[39;49;00m[43m)[49m

File [0;32m/opt/hostedtoolcache/Python/3.9.19/x64/lib/python3.9/site-packages/geopandas/geodataframe.py:2111[0m, in [0;36mGeoDataFrame.explore[0;34m(self, *args, **kwargs)[0m
[1;32m   2109[0m [38;5;129m@doc[39m(_explore)
[1;32m   2110[0m [38;5;28;01mdef[39;00m [38;5;21mexplore[39m([38;5;28mself[39m, [38;5;241m*[39margs, [38;5;241m*[39m[38;5;241m*[39mkwargs):
[0;32m-> 2111[0m     [38;5;28;01mreturn[39;00m [43m_explore[49m[43m([49m[38;5;28;43mself[39;49m[43m,[49m[43m [49m[38;5;241;43m*[39;49m[43margs[49m[43m,[49m[43m [49m[38;5;241;43m*[39;49m[38;5;241;43m*[39;49m[43mkwargs[49m[43m)[49m

File [0;32m/opt/hostedtoolcache/Python/3.9.19/x64/lib/python3.9/site-packages/geopandas/explore.py:296[0m, in [0;36m_explore[0;34m(df, column, cmap, color, m, tiles, attr, tooltip, popup, highlight, categorical, legend, scheme, k, vmin, vmax, width, height, categories, classification_kwds, control_scale, marker_type, marker_kwds, style_kwds, highlight_kwds, missing_kwds, tooltip_kwds, popup_kwds, legend_kwds, map_kwds, **kwargs)[0m
[1;32m    293[0m         [38;5;28;01mfrom[39;00m [38;5;21;01mmatplotlib[39;00m [38;5;28;01mimport[39;00m cm
[1;32m    295[0m [38;5;28;01mexcept[39;00m ([38;5;167;01mImportError[39;00m, [38;5;167;01mModuleNotFoundError[39;00m):
[0;32m--> 296[0m     [38;5;28;01mraise[39;00m [38;5;167;01mImportError[39;00m(
[1;32m    297[0m         [38;5;124m"[39m[38;5;124mThe [39m[38;5;124m'[39m[38;5;124mfolium[39m[38;5;124m'[39m[38;5;124m, [39m[38;5;124m'[39m[38;5;124mmatplotlib[39m[38;5;124m'[39m[38;5;124m and [39m[38;5;124m'[39m[38;5;124mmapclassify[39m[38;5;124m'[39m[38;5;124m packages are required for [39m[38;5;124m"[39m
[1;32m    298[0m         [38;5;124m"[39m[38;5;124m'[39m[38;5;124mexplore()[39m[38;5;124m'[39m[38;5;124m. You can install them using [39m[38;5;124m"[39m
[1;32m    299[0m         [38;5;124m"[39m[38;5;124m'[39m[38;5;124mconda install -c conda-forge folium matplotlib mapclassify[39m[38;5;124m'[39m[38;5;124m [39m[38;5;124m"[39m
[1;32m    300[0m         [38;5;124m"[39m[38;5;124mor [39m[38;5;124m'[39m[38;5;124mpip install folium matplotlib mapclassify[39m[38;5;124m'[39m[38;5;124m.[39m[38;5;124m"[39m
[1;32m    301[0m     )
[1;32m    303[0m [38;5;66;03m# xyservices is an optional dependency[39;00m
[1;32m    304[0m [38;5;28;01mtry[39;00m:

[0;31mImportError[0m: The 'folium', 'matplotlib' and 'mapclassify' packages are required for 'explore()'. You can install them using 'conda install -c conda-forge folium matplotlib mapclassify' or 'pip install folium matplotlib mapclassify'.

